[I 00:53:47.881 NotebookApp] Serving notebooks from local directory: /home/danil/Documents/Learning
[I 00:53:47.881 NotebookApp] Jupyter Notebook 6.4.4 is running at:
[I 00:53:47.881 NotebookApp] http://localhost:8888/?token=7e2b8602c0c46a61e3fb7e4ee6c26b216695ed7df1affe61
[I 00:53:47.881 NotebookApp]  or http://127.0.0.1:8888/?token=7e2b8602c0c46a61e3fb7e4ee6c26b216695ed7df1affe61
[I 00:53:47.881 NotebookApp] Use Control-C to stop this server and shut down all kernels (twice to skip confirmation).
[C 00:53:47.901 NotebookApp] 
    
    To access the notebook, open this file in a browser:
        file:///home/danil/.local/share/jupyter/runtime/nbserver-10248-open.html
    Or copy and paste one of these URLs:
        http://localhost:8888/?token=7e2b8602c0c46a61e3fb7e4ee6c26b216695ed7df1affe61
     or http://127.0.0.1:8888/?token=7e2b8602c0c46a61e3fb7e4ee6c26b216695ed7df1affe61
/usr/lib/python3.8/json/encoder.py:257: UserWarning: date_default is deprecated since jupyter_client 7.0.0. Use jupyter_client.jsonutil.json_default.
  return _iterencode(o, 0)
[W 00:54:58.099 NotebookApp] delete /DataScience/LinearModels/a.out
[W 00:54:58.129 NotebookApp] delete /DataScience/LinearModels/nohup.out
ERROR:asyncio:Exception in callback <TaskWakeupMethWrapper object at 0x7ff067d80460>(<Future finis...ea2"\r\n\r\n'>)
handle: <Handle <TaskWakeupMethWrapper object at 0x7ff067d80460>(<Future finis...ea2"\r\n\r\n'>)>
Traceback (most recent call last):
  File "/usr/lib/python3.8/asyncio/events.py", line 81, in _run
    self._context.run(self._callback, *self._args)
RuntimeError: Cannot enter into task <Task pending name='Task-12' coro=<HTTP1ServerConnection._server_request_loop() running at /home/danil/.local/lib/python3.8/site-packages/tornado/http1connection.py:823> wait_for=<Future finished result=b'GET /api/co...4ea2"\r\n\r\n'> cb=[IOLoop.add_future.<locals>.<lambda>() at /home/danil/.local/lib/python3.8/site-packages/tornado/ioloop.py:688]> while another task <Task pending name='Task-1' coro=<MultiKernelManager._async_start_kernel() running at /home/danil/.local/lib/python3.8/site-packages/jupyter_client/multikernelmanager.py:186>> is being executed.
ERROR:asyncio:Exception in callback <TaskWakeupMethWrapper object at 0x7ff0669e0a90>(<Future finis...ea2"\r\n\r\n'>)
handle: <Handle <TaskWakeupMethWrapper object at 0x7ff0669e0a90>(<Future finis...ea2"\r\n\r\n'>)>
Traceback (most recent call last):
  File "/usr/lib/python3.8/asyncio/events.py", line 81, in _run
    self._context.run(self._callback, *self._args)
RuntimeError: Cannot enter into task <Task pending name='Task-2' coro=<HTTP1ServerConnection._server_request_loop() running at /home/danil/.local/lib/python3.8/site-packages/tornado/http1connection.py:823> wait_for=<Future finished result=b'GET /nbexte...4ea2"\r\n\r\n'> cb=[IOLoop.add_future.<locals>.<lambda>() at /home/danil/.local/lib/python3.8/site-packages/tornado/ioloop.py:688]> while another task <Task pending name='Task-2' coro=<KernelManager._async_start_kernel() running at /home/danil/.local/lib/python3.8/site-packages/jupyter_client/manager.py:337>> is being executed.
ERROR:asyncio:Exception in callback <TaskWakeupMethWrapper object at 0x7ff067f272b0>(<Future finis... GMT\r\n\r\n'>)
handle: <Handle <TaskWakeupMethWrapper object at 0x7ff067f272b0>(<Future finis... GMT\r\n\r\n'>)>
Traceback (most recent call last):
  File "/usr/lib/python3.8/asyncio/events.py", line 81, in _run
    self._context.run(self._callback, *self._args)
RuntimeError: Cannot enter into task <Task pending name='Task-1' coro=<HTTP1ServerConnection._server_request_loop() running at /home/danil/.local/lib/python3.8/site-packages/tornado/http1connection.py:823> wait_for=<Future finished result=b'GET /static...6 GMT\r\n\r\n'> cb=[IOLoop.add_future.<locals>.<lambda>() at /home/danil/.local/lib/python3.8/site-packages/tornado/ioloop.py:688]> while another task <Task pending name='Task-1' coro=<MultiKernelManager._async_start_kernel() running at /home/danil/.local/lib/python3.8/site-packages/jupyter_client/multikernelmanager.py:186>> is being executed.
[I 00:55:00.445 NotebookApp] Kernel started: 9b831c9b-8ef6-4dd9-943f-3e32d85f5efa, name: python3
[W 00:55:32.074 NotebookApp] 404 GET /nbextensions/widgets/notebook/js/extension.js?v=20221116005347 (127.0.0.1) 9.550000ms referer=http://localhost:8888/notebooks/DataScience/LinearModels/LinearModels.ipynb
[I 00:57:00.466 NotebookApp] Saving file at /DataScience/LinearModels/LinearModels.ipynb
[I 00:59:00.469 NotebookApp] Saving file at /DataScience/LinearModels/LinearModels.ipynb
[I 01:01:00.455 NotebookApp] Saving file at /DataScience/LinearModels/LinearModels.ipynb
[I 01:03:00.458 NotebookApp] Saving file at /DataScience/LinearModels/LinearModels.ipynb
[I 01:05:00.456 NotebookApp] Saving file at /DataScience/LinearModels/LinearModels.ipynb
[I 01:07:00.455 NotebookApp] Saving file at /DataScience/LinearModels/LinearModels.ipynb
[I 01:09:00.457 NotebookApp] Saving file at /DataScience/LinearModels/LinearModels.ipynb
[I 01:11:00.458 NotebookApp] Saving file at /DataScience/LinearModels/LinearModels.ipynb
[I 01:13:00.440 NotebookApp] Saving file at /DataScience/LinearModels/LinearModels.ipynb
[I 01:15:00.465 NotebookApp] Saving file at /DataScience/LinearModels/LinearModels.ipynb
[I 01:17:00.461 NotebookApp] Saving file at /DataScience/LinearModels/LinearModels.ipynb
[I 01:19:00.460 NotebookApp] Saving file at /DataScience/LinearModels/LinearModels.ipynb
[I 01:21:00.465 NotebookApp] Saving file at /DataScience/LinearModels/LinearModels.ipynb
[I 01:21:58.035 NotebookApp] The port 8888 is already in use, trying another port.
[I 01:21:58.036 NotebookApp] Serving notebooks from local directory: /home/danil/Documents/Learning
[I 01:21:58.036 NotebookApp] Jupyter Notebook 6.4.4 is running at:
[I 01:21:58.036 NotebookApp] http://localhost:8889/?token=97df0751a228c5e747362c4e5ddb46c35c1c6b900a5a7383
[I 01:21:58.036 NotebookApp]  or http://127.0.0.1:8889/?token=97df0751a228c5e747362c4e5ddb46c35c1c6b900a5a7383
[I 01:21:58.036 NotebookApp] Use Control-C to stop this server and shut down all kernels (twice to skip confirmation).
[C 01:21:58.056 NotebookApp] 
    
    To access the notebook, open this file in a browser:
        file:///home/danil/.local/share/jupyter/runtime/nbserver-11569-open.html
    Or copy and paste one of these URLs:
        http://localhost:8889/?token=97df0751a228c5e747362c4e5ddb46c35c1c6b900a5a7383
     or http://127.0.0.1:8889/?token=97df0751a228c5e747362c4e5ddb46c35c1c6b900a5a7383
/usr/lib/python3.8/json/encoder.py:257: UserWarning: date_default is deprecated since jupyter_client 7.0.0. Use jupyter_client.jsonutil.json_default.
  return _iterencode(o, 0)
[I 01:22:10.059 NotebookApp] Creating new notebook in /DataScience/LinearModels
ERROR:asyncio:Exception in callback <TaskWakeupMethWrapper object at 0x7f49660b8a90>(<Future finis...3d6"\r\n\r\n'>)
handle: <Handle <TaskWakeupMethWrapper object at 0x7f49660b8a90>(<Future finis...3d6"\r\n\r\n'>)>
Traceback (most recent call last):
  File "/usr/lib/python3.8/asyncio/events.py", line 81, in _run
    self._context.run(self._callback, *self._args)
RuntimeError: Cannot enter into task <Task pending name='Task-1' coro=<HTTP1ServerConnection._server_request_loop() running at /home/danil/.local/lib/python3.8/site-packages/tornado/http1connection.py:823> wait_for=<Future finished result=b'GET /api/co...53d6"\r\n\r\n'> cb=[IOLoop.add_future.<locals>.<lambda>() at /home/danil/.local/lib/python3.8/site-packages/tornado/ioloop.py:688]> while another task <Task pending name='Task-2' coro=<KernelManager._async_start_kernel() running at /home/danil/.local/lib/python3.8/site-packages/jupyter_client/manager.py:336>> is being executed.
[I 01:22:11.581 NotebookApp] Kernel started: 555b296f-e002-4133-819c-8c8cc1a61f81, name: python3
[W 01:22:11.595 NotebookApp] 404 GET /nbextensions/widgets/notebook/js/extension.js?v=20221116012157 (127.0.0.1) 11.370000ms referer=http://localhost:8889/notebooks/DataScience/LinearModels/Untitled.ipynb?kernel_name=python3
[I 01:23:01.076 NotebookApp] Saving file at /DataScience/LinearModels/Regression task.ipynb
[W 01:23:06.644 NotebookApp] Notebook DataScience/LinearModels/Regression task.ipynb is not trusted
ERROR:asyncio:Exception in callback <TaskWakeupMethWrapper object at 0x7f4962ec3700>(<Future finis...3d6"\r\n\r\n'>)
handle: <Handle <TaskWakeupMethWrapper object at 0x7f4962ec3700>(<Future finis...3d6"\r\n\r\n'>)>
Traceback (most recent call last):
  File "/usr/lib/python3.8/asyncio/events.py", line 81, in _run
    self._context.run(self._callback, *self._args)
RuntimeError: Cannot enter into task <Task pending name='Task-7' coro=<HTTP1ServerConnection._server_request_loop() running at /home/danil/.local/lib/python3.8/site-packages/tornado/http1connection.py:823> wait_for=<Future finished result=b'GET /api/co...53d6"\r\n\r\n'> cb=[IOLoop.add_future.<locals>.<lambda>() at /home/danil/.local/lib/python3.8/site-packages/tornado/ioloop.py:688]> while another task <Task pending name='Task-63' coro=<KernelManager._async_start_kernel() running at /home/danil/.local/lib/python3.8/site-packages/jupyter_client/manager.py:337>> is being executed.
[I 01:23:07.072 NotebookApp] Kernel started: f3496f14-ce7a-45f0-aee1-00467fc29af9, name: python3
[W 01:23:07.221 NotebookApp] 404 GET /nbextensions/widgets/notebook/js/extension.js?v=20221116012157 (127.0.0.1) 3.680000ms referer=http://localhost:8889/notebooks/DataScience/LinearModels/Regression%20task.ipynb
[I 01:24:11.611 NotebookApp] Saving file at /DataScience/LinearModels/Classification task.ipynb
[I 01:26:11.597 NotebookApp] Saving file at /DataScience/LinearModels/Classification task.ipynb
[I 01:28:11.596 NotebookApp] Saving file at /DataScience/LinearModels/Classification task.ipynb
[I 01:30:11.575 NotebookApp] Saving file at /DataScience/LinearModels/Classification task.ipynb
[I 01:32:11.598 NotebookApp] Saving file at /DataScience/LinearModels/Classification task.ipynb
[W 01:33:01.996 NotebookApp] Notebook DataScience/LinearModels/CourseraTask/task-3.1.ipynb is not trusted
[I 01:33:02.284 NotebookApp] Kernel started: b11f7ae8-17c0-4eda-8e28-828cb5f5929a, name: python3
[W 01:33:02.343 NotebookApp] 404 GET /nbextensions/widgets/notebook/js/extension.js?v=20221116012157 (127.0.0.1) 3.540000ms referer=http://localhost:8889/notebooks/DataScience/LinearModels/CourseraTask/task-3.1.ipynb
[I 01:35:02.317 NotebookApp] Saving file at /DataScience/LinearModels/CourseraTask/task-3.1.ipynb
[I 01:39:02.300 NotebookApp] Saving file at /DataScience/LinearModels/CourseraTask/task-3.1.ipynb
[I 01:41:03.114 NotebookApp] Saving file at /DataScience/LinearModels/CourseraTask/task-3.1.ipynb
[I 01:43:02.301 NotebookApp] Saving file at /DataScience/LinearModels/CourseraTask/task-3.1.ipynb
[I 01:45:03.093 NotebookApp] Saving file at /DataScience/LinearModels/CourseraTask/task-3.1.ipynb
[I 01:46:11.599 NotebookApp] Saving file at /DataScience/LinearModels/Classification task.ipynb
[E 01:46:11.622 NotebookApp] Notebook JSON is invalid: Non-unique cell id 'd3a4c6c6' detected. Corrected to '4a17d008'.
[I 01:48:12.098 NotebookApp] Saving file at /DataScience/LinearModels/Classification task.ipynb
[E 01:48:12.124 NotebookApp] Notebook JSON is invalid: Non-unique cell id 'd3a4c6c6' detected. Corrected to '7eeb5f27'.
[I 01:49:02.302 NotebookApp] Saving file at /DataScience/LinearModels/CourseraTask/task-3.1.ipynb
[I 01:50:32.294 NotebookApp] Saving file at /DataScience/LinearModels/Classification task.ipynb
[E 01:50:32.532 NotebookApp] Notebook JSON is invalid: Non-unique cell id 'd3a4c6c6' detected. Corrected to 'c7d00b36'.
[I 01:50:33.694 NotebookApp] Saving file at /DataScience/LinearModels/Regression task.ipynb
[W 01:50:33.694 NotebookApp] Notebook DataScience/LinearModels/Regression task.ipynb is not trusted
[I 01:50:52.524 NotebookApp] Saving file at /DataScience/LinearModels/Classification task.ipynb
[E 01:50:52.658 NotebookApp] Notebook JSON is invalid: Non-unique cell id 'd3a4c6c6' detected. Corrected to 'da90e474'.
[I 01:51:03.099 NotebookApp] Saving file at /DataScience/LinearModels/CourseraTask/task-3.1.ipynb
[I 01:51:07.773 NotebookApp] Starting buffering for 555b296f-e002-4133-819c-8c8cc1a61f81:05a8633a6e4e415586576d19b1a79daa
[I 01:51:08.211 NotebookApp] Kernel restarted: 555b296f-e002-4133-819c-8c8cc1a61f81
[I 01:51:08.231 NotebookApp] Restoring connection for 555b296f-e002-4133-819c-8c8cc1a61f81:05a8633a6e4e415586576d19b1a79daa
[I 01:51:08.910 NotebookApp] Replaying 3 buffered messages
[I 01:52:12.088 NotebookApp] Saving file at /DataScience/LinearModels/Classification task.ipynb
[E 01:52:12.593 NotebookApp] Notebook JSON is invalid: Non-unique cell id 'd3a4c6c6' detected. Corrected to 'e058d993'.
[I 01:53:02.313 NotebookApp] Saving file at /DataScience/LinearModels/CourseraTask/task-3.1.ipynb
[I 01:55:03.099 NotebookApp] Saving file at /DataScience/LinearModels/CourseraTask/task-3.1.ipynb
[I 01:57:02.282 NotebookApp] Saving file at /DataScience/LinearModels/CourseraTask/task-3.1.ipynb
[I 01:59:02.289 NotebookApp] Saving file at /DataScience/LinearModels/CourseraTask/task-3.1.ipynb
[I 02:01:02.300 NotebookApp] Saving file at /DataScience/LinearModels/CourseraTask/task-3.1.ipynb
[I 02:03:02.301 NotebookApp] Saving file at /DataScience/LinearModels/CourseraTask/task-3.1.ipynb
[I 02:05:02.302 NotebookApp] Saving file at /DataScience/LinearModels/CourseraTask/task-3.1.ipynb
[I 02:07:03.099 NotebookApp] Saving file at /DataScience/LinearModels/CourseraTask/task-3.1.ipynb
[I 02:09:02.301 NotebookApp] Saving file at /DataScience/LinearModels/CourseraTask/task-3.1.ipynb
[I 02:11:02.304 NotebookApp] Saving file at /DataScience/LinearModels/CourseraTask/task-3.1.ipynb
[W 02:12:25.258 NotebookApp] Notebook DataScience/LinearModels/CourseraTask/task-3.1-solution.ipynb is not trusted
[I 02:12:25.536 NotebookApp] Kernel started: c6566347-ec9a-4dbb-b83b-956649fd8e07, name: python3
[W 02:12:25.589 NotebookApp] 404 GET /nbextensions/widgets/notebook/js/extension.js?v=20221116012157 (127.0.0.1) 2.490000ms referer=http://localhost:8889/notebooks/DataScience/LinearModels/CourseraTask/task-3.1-solution.ipynb
[I 02:13:01.864 NotebookApp] Starting buffering for c6566347-ec9a-4dbb-b83b-956649fd8e07:8641f5be201a446f90792935a0927371
[I 02:13:02.407 NotebookApp] Saving file at /DataScience/LinearModels/CourseraTask/task-3.1.ipynb
[I 02:13:34.140 NotebookApp] Saving file at /DataScience/LinearModels/CourseraTask/task-3.1.ipynb
[I 02:13:35.269 NotebookApp] Saving file at /DataScience/LinearModels/Regression task.ipynb
[W 02:13:35.269 NotebookApp] Notebook DataScience/LinearModels/Regression task.ipynb is not trusted
[I 02:13:36.288 NotebookApp] Saving file at /DataScience/LinearModels/Classification task.ipynb
[E 02:13:36.302 NotebookApp] Notebook JSON is invalid: Non-unique cell id 'd3a4c6c6' detected. Corrected to 'ebc74d04'.
[I 02:13:38.959 NotebookApp] Starting buffering for b11f7ae8-17c0-4eda-8e28-828cb5f5929a:f0671c2fd98b47158a82deb575ea29cf
[I 02:13:39.201 NotebookApp] Starting buffering for f3496f14-ce7a-45f0-aee1-00467fc29af9:778ca53cee5646c3811b3c3ff337f0d8
[I 02:13:39.492 NotebookApp] Starting buffering for 555b296f-e002-4133-819c-8c8cc1a61f81:05a8633a6e4e415586576d19b1a79daa
[I 02:15:50.814 NotebookApp] Starting buffering for 9b831c9b-8ef6-4dd9-943f-3e32d85f5efa:0fcc0231b3b94696a7427c3f55093882
[I 11:33:21.558 NotebookApp] The port 8888 is already in use, trying another port.
[I 11:33:21.558 NotebookApp] The port 8889 is already in use, trying another port.
[I 11:33:21.559 NotebookApp] Serving notebooks from local directory: /home/danil/Documents/Learning
[I 11:33:21.559 NotebookApp] Jupyter Notebook 6.4.4 is running at:
[I 11:33:21.559 NotebookApp] http://localhost:8890/?token=360020995b5f71c72fd831680941d1be776e7f7b124e4296
[I 11:33:21.559 NotebookApp]  or http://127.0.0.1:8890/?token=360020995b5f71c72fd831680941d1be776e7f7b124e4296
[I 11:33:21.559 NotebookApp] Use Control-C to stop this server and shut down all kernels (twice to skip confirmation).
[C 11:33:21.579 NotebookApp] 
    
    To access the notebook, open this file in a browser:
        file:///home/danil/.local/share/jupyter/runtime/nbserver-20340-open.html
    Or copy and paste one of these URLs:
        http://localhost:8890/?token=360020995b5f71c72fd831680941d1be776e7f7b124e4296
     or http://127.0.0.1:8890/?token=360020995b5f71c72fd831680941d1be776e7f7b124e4296
/usr/lib/python3.8/json/encoder.py:257: UserWarning: date_default is deprecated since jupyter_client 7.0.0. Use jupyter_client.jsonutil.json_default.
  return _iterencode(o, 0)
[I 11:33:50.889 NotebookApp] Creating new directory in /DataScience
[I 11:34:22.566 NotebookApp] Creating new notebook in /DataScience/MetricsOfModel
ERROR:asyncio:Exception in callback <TaskWakeupMethWrapper object at 0x7fc02fc13f10>(<Future finis...2fe"\r\n\r\n'>)
handle: <Handle <TaskWakeupMethWrapper object at 0x7fc02fc13f10>(<Future finis...2fe"\r\n\r\n'>)>
Traceback (most recent call last):
  File "/usr/lib/python3.8/asyncio/events.py", line 81, in _run
    self._context.run(self._callback, *self._args)
RuntimeError: Cannot enter into task <Task pending name='Task-1' coro=<HTTP1ServerConnection._server_request_loop() running at /home/danil/.local/lib/python3.8/site-packages/tornado/http1connection.py:823> wait_for=<Future finished result=b'GET /api/co...e2fe"\r\n\r\n'> cb=[IOLoop.add_future.<locals>.<lambda>() at /home/danil/.local/lib/python3.8/site-packages/tornado/ioloop.py:688]> while another task <Task pending name='Task-2' coro=<KernelManager._async_start_kernel() running at /home/danil/.local/lib/python3.8/site-packages/jupyter_client/manager.py:336>> is being executed.
ERROR:asyncio:Exception in callback <TaskWakeupMethWrapper object at 0x7fc02f03df10>(<Future finis...2fe"\r\n\r\n'>)
handle: <Handle <TaskWakeupMethWrapper object at 0x7fc02f03df10>(<Future finis...2fe"\r\n\r\n'>)>
Traceback (most recent call last):
  File "/usr/lib/python3.8/asyncio/events.py", line 81, in _run
    self._context.run(self._callback, *self._args)
RuntimeError: Cannot enter into task <Task pending name='Task-7' coro=<HTTP1ServerConnection._server_request_loop() running at /home/danil/.local/lib/python3.8/site-packages/tornado/http1connection.py:823> wait_for=<Future finished result=b'GET /kernel...e2fe"\r\n\r\n'> cb=[IOLoop.add_future.<locals>.<lambda>() at /home/danil/.local/lib/python3.8/site-packages/tornado/ioloop.py:688]> while another task <Task pending name='Task-2' coro=<KernelManager._async_start_kernel() running at /home/danil/.local/lib/python3.8/site-packages/jupyter_client/manager.py:337>> is being executed.
[I 11:34:23.923 NotebookApp] Kernel started: 84dd8017-b865-43c9-80c0-efab778bf3fa, name: python3
[W 11:34:23.936 NotebookApp] 404 GET /nbextensions/widgets/notebook/js/extension.js?v=20221116113321 (127.0.0.1) 9.910000ms referer=http://localhost:8890/notebooks/DataScience/MetricsOfModel/Untitled.ipynb?kernel_name=python3
[I 11:36:23.933 NotebookApp] Saving file at /DataScience/MetricsOfModel/Untitled.ipynb
[E 11:37:15.995 NotebookApp] Notebook JSON is invalid: Non-unique cell id 'd3a4c6c6' detected. Corrected to '03cfa8da'.
[W 11:37:15.996 NotebookApp] Notebook DataScience/LinearModels/Classification task.ipynb is not trusted
ERROR:asyncio:Exception in callback <TaskWakeupMethWrapper object at 0x7fc02f001c40>(<Future finis...2fe"\r\n\r\n'>)
handle: <Handle <TaskWakeupMethWrapper object at 0x7fc02f001c40>(<Future finis...2fe"\r\n\r\n'>)>
Traceback (most recent call last):
  File "/usr/lib/python3.8/asyncio/events.py", line 81, in _run
    self._context.run(self._callback, *self._args)
RuntimeError: Cannot enter into task <Task pending name='Task-2' coro=<HTTP1ServerConnection._server_request_loop() running at /home/danil/.local/lib/python3.8/site-packages/tornado/http1connection.py:823> wait_for=<Future finished result=b'GET /api/co...e2fe"\r\n\r\n'> cb=[IOLoop.add_future.<locals>.<lambda>() at /home/danil/.local/lib/python3.8/site-packages/tornado/ioloop.py:688]> while another task <Task pending name='Task-114' coro=<KernelManager._async_start_kernel() running at /home/danil/.local/lib/python3.8/site-packages/jupyter_client/manager.py:337>> is being executed.
[I 11:37:16.344 NotebookApp] Kernel started: 7c4a580b-c45e-460c-b2a9-710c99fb481c, name: python3
[W 11:37:16.443 NotebookApp] 404 GET /nbextensions/widgets/notebook/js/extension.js?v=20221116113321 (127.0.0.1) 3.550000ms referer=http://localhost:8890/notebooks/DataScience/LinearModels/Classification%20task.ipynb
[I 11:37:26.155 NotebookApp] Starting buffering for 7c4a580b-c45e-460c-b2a9-710c99fb481c:befba7a5435d4f1389f57404c6f289bd
[I 11:38:23.934 NotebookApp] Saving file at /DataScience/MetricsOfModel/UsingOfMetrics.ipynb
[I 11:40:23.914 NotebookApp] Saving file at /DataScience/MetricsOfModel/UsingOfMetrics.ipynb
[I 11:42:23.935 NotebookApp] Saving file at /DataScience/MetricsOfModel/UsingOfMetrics.ipynb
[E 11:42:40.209 NotebookApp] Notebook JSON is invalid: Non-unique cell id 'd3a4c6c6' detected. Corrected to '95dddae3'.
[W 11:42:40.210 NotebookApp] Notebook DataScience/LinearModels/Classification task.ipynb is not trusted
[W 11:42:40.663 NotebookApp] 404 GET /nbextensions/widgets/notebook/js/extension.js?v=20221116113321 (127.0.0.1) 2.460000ms referer=http://localhost:8890/notebooks/DataScience/LinearModels/Classification%20task.ipynb
[I 11:42:45.535 NotebookApp] Starting buffering for 7c4a580b-c45e-460c-b2a9-710c99fb481c:d05dead1d3564a628410d24db6da4bcb
[I 11:44:23.935 NotebookApp] Saving file at /DataScience/MetricsOfModel/UsingOfMetrics.ipynb
[E 11:44:23.952 NotebookApp] Notebook JSON is invalid: Non-unique cell id 'd3a4c6c6' detected. Corrected to '4f15a9de'.
[I 11:44:38.347 NotebookApp] Saving file at /DataScience/MetricsOfModel/UsingOfMetrics.ipynb
[E 11:44:38.355 NotebookApp] Notebook JSON is invalid: Non-unique cell id 'd3a4c6c6' detected. Corrected to '01dbf67e'.
[I 11:44:40.732 NotebookApp] Saving file at /DataScience/MetricsOfModel/UsingOfMetrics.ipynb
[E 11:44:40.752 NotebookApp] Notebook JSON is invalid: Non-unique cell id 'd3a4c6c6' detected. Corrected to '99b04450'.
[I 11:44:45.660 NotebookApp] Starting buffering for 84dd8017-b865-43c9-80c0-efab778bf3fa:8a43d3aeda654d899966d4a7064d8f24
[E 11:44:46.054 NotebookApp] Notebook JSON is invalid: Non-unique cell id 'd3a4c6c6' detected. Corrected to '8ccd6b86'.
[W 11:44:46.055 NotebookApp] Notebook DataScience/MetricsOfModel/UsingOfMetrics.ipynb is not trusted
[W 11:44:46.280 NotebookApp] 404 GET /nbextensions/widgets/notebook/js/extension.js?v=20221116113321 (127.0.0.1) 3.110000ms referer=http://localhost:8890/notebooks/DataScience/MetricsOfModel/UsingOfMetrics.ipynb
[I 11:44:48.317 NotebookApp] Saving file at /DataScience/MetricsOfModel/UsingOfMetrics.ipynb
[I 11:46:46.270 NotebookApp] Saving file at /DataScience/MetricsOfModel/UsingOfMetrics.ipynb
[I 11:48:46.241 NotebookApp] Saving file at /DataScience/MetricsOfModel/UsingOfMetrics.ipynb
[I 11:50:46.232 NotebookApp] Saving file at /DataScience/MetricsOfModel/UsingOfMetrics.ipynb
[I 11:52:46.254 NotebookApp] Saving file at /DataScience/MetricsOfModel/UsingOfMetrics.ipynb
[I 11:56:46.241 NotebookApp] Saving file at /DataScience/MetricsOfModel/UsingOfMetrics.ipynb
[I 11:58:42.693 NotebookApp] Saving file at /DataScience/MetricsOfModel/UsingOfMetrics.ipynb
[I 12:00:46.254 NotebookApp] Saving file at /DataScience/MetricsOfModel/UsingOfMetrics.ipynb
[I 12:01:32.591 NotebookApp] Saving file at /DataScience/MetricsOfModel/UsingOfMetrics.ipynb
[E 12:01:32.682 NotebookApp] Notebook JSON is invalid: Non-unique cell id '8ccd6b86' detected. Corrected to '3ee17608'.
[I 12:01:51.069 NotebookApp] Saving file at /DataScience/MetricsOfModel/UsingOfMetrics.ipynb
[I 12:02:13.897 NotebookApp] Saving file at /DataScience/MetricsOfModel/UsingOfMetrics.ipynb
[I 12:02:17.161 NotebookApp] Saving file at /DataScience/MetricsOfModel/UsingOfMetrics.ipynb
[I 12:02:46.263 NotebookApp] Saving file at /DataScience/MetricsOfModel/UsingOfMetrics.ipynb
[I 12:04:46.678 NotebookApp] Saving file at /DataScience/MetricsOfModel/UsingOfMetrics.ipynb
[W 12:07:57.633 NotebookApp] Notebook DataScience/MetricsOfModel/CourseraTask/regularization task.ipynb is not trusted
[I 12:07:58.244 NotebookApp] Kernel started: 39e4e0ac-2728-4d83-a128-13566fbeddd5, name: python3
[W 12:07:58.334 NotebookApp] 404 GET /nbextensions/widgets/notebook/js/extension.js?v=20221116113321 (127.0.0.1) 3.760000ms referer=http://localhost:8890/notebooks/DataScience/MetricsOfModel/CourseraTask/regularization%20task.ipynb
[I 12:09:58.250 NotebookApp] Saving file at /DataScience/MetricsOfModel/CourseraTask/regularization task.ipynb
[I 12:13:58.276 NotebookApp] Saving file at /DataScience/MetricsOfModel/CourseraTask/regularization task.ipynb
[I 12:15:58.259 NotebookApp] Saving file at /DataScience/MetricsOfModel/CourseraTask/regularization task.ipynb
[I 12:17:58.259 NotebookApp] Saving file at /DataScience/MetricsOfModel/CourseraTask/regularization task.ipynb
[I 12:21:58.259 NotebookApp] Saving file at /DataScience/MetricsOfModel/CourseraTask/regularization task.ipynb
[I 12:23:58.258 NotebookApp] Saving file at /DataScience/MetricsOfModel/CourseraTask/regularization task.ipynb
[I 12:25:58.680 NotebookApp] Saving file at /DataScience/MetricsOfModel/CourseraTask/regularization task.ipynb
[W 12:37:57.199 NotebookApp] Notebook DataScience/MetricsOfModel/CourseraTask/Metrics/task-3.2.2.ipynb is not trusted
[I 12:37:57.597 NotebookApp] Kernel started: a22cf079-68c5-43ae-afb1-45ca9ccb5d77, name: python3
[W 12:37:57.682 NotebookApp] 404 GET /nbextensions/widgets/notebook/js/extension.js?v=20221116113321 (127.0.0.1) 4.100000ms referer=http://localhost:8890/notebooks/DataScience/MetricsOfModel/CourseraTask/Metrics/task-3.2.2.ipynb
[I 12:39:57.617 NotebookApp] Saving file at /DataScience/MetricsOfModel/CourseraTask/Metrics/task-3.2.2.ipynb
[I 12:41:57.595 NotebookApp] Saving file at /DataScience/MetricsOfModel/CourseraTask/Metrics/task-3.2.2.ipynb
[I 12:43:57.612 NotebookApp] Saving file at /DataScience/MetricsOfModel/CourseraTask/Metrics/task-3.2.2.ipynb
[I 12:45:57.612 NotebookApp] Saving file at /DataScience/MetricsOfModel/CourseraTask/Metrics/task-3.2.2.ipynb
[I 12:47:57.612 NotebookApp] Saving file at /DataScience/MetricsOfModel/CourseraTask/Metrics/task-3.2.2.ipynb
[I 12:49:57.614 NotebookApp] Saving file at /DataScience/MetricsOfModel/CourseraTask/Metrics/task-3.2.2.ipynb
[I 12:51:57.615 NotebookApp] Saving file at /DataScience/MetricsOfModel/CourseraTask/Metrics/task-3.2.2.ipynb
[I 12:53:57.612 NotebookApp] Saving file at /DataScience/MetricsOfModel/CourseraTask/Metrics/task-3.2.2.ipynb
[W 12:55:41.179 NotebookApp] Notebook DataScience/MetricsOfModel/CourseraTask/Metrics/task-3.2.2-solution.ipynb is not trusted
[I 12:55:41.568 NotebookApp] Kernel started: c3c42693-3544-4613-aa3d-48194302a865, name: python3
[W 12:55:41.637 NotebookApp] 404 GET /nbextensions/widgets/notebook/js/extension.js?v=20221116113321 (127.0.0.1) 4.130000ms referer=http://localhost:8890/notebooks/DataScience/MetricsOfModel/CourseraTask/Metrics/task-3.2.2-solution.ipynb
[I 12:56:17.939 NotebookApp] Starting buffering for c3c42693-3544-4613-aa3d-48194302a865:312264de66204c8281df22695ac885a2
[I 12:56:18.177 NotebookApp] Kernel restarted: c3c42693-3544-4613-aa3d-48194302a865
[I 12:56:18.198 NotebookApp] Restoring connection for c3c42693-3544-4613-aa3d-48194302a865:312264de66204c8281df22695ac885a2
[I 12:56:19.211 NotebookApp] Replaying 3 buffered messages
[I 12:57:41.582 NotebookApp] Saving file at /DataScience/MetricsOfModel/CourseraTask/Metrics/task-3.2.2-solution.ipynb
[I 12:59:57.609 NotebookApp] Saving file at /DataScience/MetricsOfModel/CourseraTask/Metrics/task-3.2.2.ipynb
[I 13:01:57.612 NotebookApp] Saving file at /DataScience/MetricsOfModel/CourseraTask/Metrics/task-3.2.2.ipynb
[I 13:03:57.612 NotebookApp] Saving file at /DataScience/MetricsOfModel/CourseraTask/Metrics/task-3.2.2.ipynb
[I 13:05:57.600 NotebookApp] Saving file at /DataScience/MetricsOfModel/CourseraTask/Metrics/task-3.2.2.ipynb
[I 13:07:57.611 NotebookApp] Saving file at /DataScience/MetricsOfModel/CourseraTask/Metrics/task-3.2.2.ipynb
[I 13:09:57.610 NotebookApp] Saving file at /DataScience/MetricsOfModel/CourseraTask/Metrics/task-3.2.2.ipynb
[I 13:11:57.680 NotebookApp] Saving file at /DataScience/MetricsOfModel/CourseraTask/Metrics/task-3.2.2.ipynb
[I 13:12:58.776 NotebookApp] Starting buffering for c3c42693-3544-4613-aa3d-48194302a865:312264de66204c8281df22695ac885a2
[I 13:12:59.115 NotebookApp] Kernel restarted: c3c42693-3544-4613-aa3d-48194302a865
[I 13:12:59.135 NotebookApp] Restoring connection for c3c42693-3544-4613-aa3d-48194302a865:312264de66204c8281df22695ac885a2
[I 13:13:00.149 NotebookApp] Replaying 3 buffered messages
[I 13:13:23.962 NotebookApp] Saving file at /DataScience/MetricsOfModel/CourseraTask/Metrics/task-3.2.2-solution.ipynb
[I 13:13:25.028 NotebookApp] Saving file at /DataScience/MetricsOfModel/CourseraTask/Metrics/task-3.2.2-solution.ipynb
[I 13:13:25.919 NotebookApp] Starting buffering for c3c42693-3544-4613-aa3d-48194302a865:312264de66204c8281df22695ac885a2
[I 13:13:27.126 NotebookApp] Saving file at /DataScience/MetricsOfModel/CourseraTask/Metrics/task-3.2.2.ipynb
[I 13:13:27.849 NotebookApp] Starting buffering for a22cf079-68c5-43ae-afb1-45ca9ccb5d77:8103bb8e41664f0a9aad82b49fdf76ba
[I 13:13:28.286 NotebookApp] Saving file at /DataScience/MetricsOfModel/UsingOfMetrics.ipynb
[I 13:13:28.842 NotebookApp] Starting buffering for 84dd8017-b865-43c9-80c0-efab778bf3fa:b988fa58db55474c9b7280091bda1aa9
[I 13:13:29.282 NotebookApp] Saving file at /DataScience/MetricsOfModel/CourseraTask/regularization task.ipynb
[I 13:13:29.762 NotebookApp] Starting buffering for 39e4e0ac-2728-4d83-a128-13566fbeddd5:68baf0bf63be484c892c657bca52dc69
[I 12:37:17.557 NotebookApp] Serving notebooks from local directory: /home/danil/Documents/Learning
[I 12:37:17.558 NotebookApp] Jupyter Notebook 6.4.4 is running at:
[I 12:37:17.558 NotebookApp] http://localhost:8888/?token=007c6998d323eb754b2d541462a7f9f4858dadf883c6437a
[I 12:37:17.558 NotebookApp]  or http://127.0.0.1:8888/?token=007c6998d323eb754b2d541462a7f9f4858dadf883c6437a
[I 12:37:17.558 NotebookApp] Use Control-C to stop this server and shut down all kernels (twice to skip confirmation).
[C 12:37:17.588 NotebookApp] 
    
    To access the notebook, open this file in a browser:
        file:///home/danil/.local/share/jupyter/runtime/nbserver-4812-open.html
    Or copy and paste one of these URLs:
        http://localhost:8888/?token=007c6998d323eb754b2d541462a7f9f4858dadf883c6437a
     or http://127.0.0.1:8888/?token=007c6998d323eb754b2d541462a7f9f4858dadf883c6437a
/usr/lib/python3.8/json/encoder.py:257: UserWarning: date_default is deprecated since jupyter_client 7.0.0. Use jupyter_client.jsonutil.json_default.
  return _iterencode(o, 0)
[I 13:46:14.610 NotebookApp] Creating new directory in /DataScience
[I 13:47:24.872 NotebookApp] Creating new notebook in /DataScience/EnsembleModels
ERROR:asyncio:Exception in callback <TaskWakeupMethWrapper object at 0x7efdd80f8640>(<Future finis...f7e"\r\n\r\n'>)
handle: <Handle <TaskWakeupMethWrapper object at 0x7efdd80f8640>(<Future finis...f7e"\r\n\r\n'>)>
Traceback (most recent call last):
  File "/usr/lib/python3.8/asyncio/events.py", line 81, in _run
    self._context.run(self._callback, *self._args)
RuntimeError: Cannot enter into task <Task pending name='Task-62' coro=<HTTP1ServerConnection._server_request_loop() running at /home/danil/.local/lib/python3.8/site-packages/tornado/http1connection.py:823> wait_for=<Future finished result=b'GET /api/co...af7e"\r\n\r\n'> cb=[IOLoop.add_future.<locals>.<lambda>() at /home/danil/.local/lib/python3.8/site-packages/tornado/ioloop.py:688]> while another task <Task pending name='Task-2' coro=<KernelManager._async_start_kernel() running at /home/danil/.local/lib/python3.8/site-packages/jupyter_client/manager.py:336>> is being executed.
ERROR:asyncio:Exception in callback <TaskWakeupMethWrapper object at 0x7efdd8aee6a0>(<Future finis...f7e"\r\n\r\n'>)
handle: <Handle <TaskWakeupMethWrapper object at 0x7efdd8aee6a0>(<Future finis...f7e"\r\n\r\n'>)>
Traceback (most recent call last):
  File "/usr/lib/python3.8/asyncio/events.py", line 81, in _run
    self._context.run(self._callback, *self._args)
RuntimeError: Cannot enter into task <Task pending name='Task-83' coro=<HTTP1ServerConnection._server_request_loop() running at /home/danil/.local/lib/python3.8/site-packages/tornado/http1connection.py:823> wait_for=<Future finished result=b'GET /kernel...af7e"\r\n\r\n'> cb=[IOLoop.add_future.<locals>.<lambda>() at /home/danil/.local/lib/python3.8/site-packages/tornado/ioloop.py:688]> while another task <Task pending name='Task-2' coro=<KernelManager._async_start_kernel() running at /home/danil/.local/lib/python3.8/site-packages/jupyter_client/manager.py:337>> is being executed.
ERROR:asyncio:Exception in callback <TaskWakeupMethWrapper object at 0x7efdd80f8040>(<Future finis...f7e"\r\n\r\n'>)
handle: <Handle <TaskWakeupMethWrapper object at 0x7efdd80f8040>(<Future finis...f7e"\r\n\r\n'>)>
Traceback (most recent call last):
  File "/usr/lib/python3.8/asyncio/events.py", line 81, in _run
    self._context.run(self._callback, *self._args)
RuntimeError: Cannot enter into task <Task pending name='Task-85' coro=<HTTP1ServerConnection._server_request_loop() running at /home/danil/.local/lib/python3.8/site-packages/tornado/http1connection.py:823> wait_for=<Future finished result=b'GET /nbexte...af7e"\r\n\r\n'> cb=[IOLoop.add_future.<locals>.<lambda>() at /home/danil/.local/lib/python3.8/site-packages/tornado/ioloop.py:688]> while another task <Task pending name='Task-97' coro=<MappingKernelManager.start_kernel() running at /home/danil/.local/lib/python3.8/site-packages/notebook/services/kernels/kernelmanager.py:176> cb=[IOLoop.add_future.<locals>.<lambda>() at /home/danil/.local/lib/python3.8/site-packages/tornado/ioloop.py:688]> is being executed.
[I 13:47:26.379 NotebookApp] Kernel started: dde38265-2e89-46fc-95fc-afc130dc195a, name: python3
[E 13:48:04.052 NotebookApp] Notebook JSON is invalid: Non-unique cell id 'd3a4c6c6' detected. Corrected to '5853d4f5'.
[W 13:48:04.054 NotebookApp] Notebook DataScience/LinearModels/Classification task.ipynb is not trusted
ERROR:asyncio:Exception in callback <TaskWakeupMethWrapper object at 0x7efdd8c99bb0>(<Future finis...f7e"\r\n\r\n'>)
handle: <Handle <TaskWakeupMethWrapper object at 0x7efdd8c99bb0>(<Future finis...f7e"\r\n\r\n'>)>
Traceback (most recent call last):
  File "/usr/lib/python3.8/asyncio/events.py", line 81, in _run
    self._context.run(self._callback, *self._args)
RuntimeError: Cannot enter into task <Task pending name='Task-57' coro=<HTTP1ServerConnection._server_request_loop() running at /home/danil/.local/lib/python3.8/site-packages/tornado/http1connection.py:823> wait_for=<Future finished result=b'GET /api/co...af7e"\r\n\r\n'> cb=[IOLoop.add_future.<locals>.<lambda>() at /home/danil/.local/lib/python3.8/site-packages/tornado/ioloop.py:688]> while another task <Task pending name='Task-53' coro=<KernelManager._async_start_kernel() running at /home/danil/.local/lib/python3.8/site-packages/jupyter_client/manager.py:337>> is being executed.
[I 13:48:04.441 NotebookApp] Kernel started: 53faea53-9331-4cf7-82c2-970bb61b0315, name: python3
[I 13:48:08.525 NotebookApp] Starting buffering for 53faea53-9331-4cf7-82c2-970bb61b0315:e0bb3d509b6345bf93dd8581a8e26d5b
[I 13:49:26.595 NotebookApp] Saving file at /DataScience/EnsembleModels/EnsembleModels.ipynb
[I 13:51:26.579 NotebookApp] Saving file at /DataScience/EnsembleModels/EnsembleModels.ipynb
[I 13:53:26.590 NotebookApp] Saving file at /DataScience/EnsembleModels/EnsembleModels.ipynb
[I 13:55:26.590 NotebookApp] Saving file at /DataScience/EnsembleModels/EnsembleModels.ipynb
[I 13:59:26.570 NotebookApp] Saving file at /DataScience/EnsembleModels/EnsembleModels.ipynb
[I 14:01:26.591 NotebookApp] Saving file at /DataScience/EnsembleModels/EnsembleModels.ipynb
[I 14:03:26.395 NotebookApp] Saving file at /DataScience/EnsembleModels/EnsembleModels.ipynb
[I 14:05:26.590 NotebookApp] Saving file at /DataScience/EnsembleModels/EnsembleModels.ipynb
[I 14:06:42.780 NotebookApp] Saving file at /DataScience/EnsembleModels/EnsembleModels.ipynb
[I 14:07:34.662 NotebookApp] Starting buffering for dde38265-2e89-46fc-95fc-afc130dc195a:80014da9aa3b46159956c87a4abdb8cf
[I 09:47:36.662 NotebookApp] Serving notebooks from local directory: /home/danil/Documents/Learning
[I 09:47:36.662 NotebookApp] Jupyter Notebook 6.4.4 is running at:
[I 09:47:36.662 NotebookApp] http://localhost:8888/?token=609c0049f28b26117ab4391bcb354aca3054fa24f8f07feb
[I 09:47:36.662 NotebookApp]  or http://127.0.0.1:8888/?token=609c0049f28b26117ab4391bcb354aca3054fa24f8f07feb
[I 09:47:36.662 NotebookApp] Use Control-C to stop this server and shut down all kernels (twice to skip confirmation).
[C 09:47:36.687 NotebookApp] 
    
    To access the notebook, open this file in a browser:
        file:///home/danil/.local/share/jupyter/runtime/nbserver-4900-open.html
    Or copy and paste one of these URLs:
        http://localhost:8888/?token=609c0049f28b26117ab4391bcb354aca3054fa24f8f07feb
     or http://127.0.0.1:8888/?token=609c0049f28b26117ab4391bcb354aca3054fa24f8f07feb
[I 09:47:54.947 NotebookApp] The port 8888 is already in use, trying another port.
[I 09:47:54.948 NotebookApp] Serving notebooks from local directory: /home/danil/Documents/Learning
[I 09:47:54.948 NotebookApp] Jupyter Notebook 6.4.4 is running at:
[I 09:47:54.948 NotebookApp] http://localhost:8889/?token=ead333178d7922419e7de2c698d79688c6202fe4ec4707fb
[I 09:47:54.948 NotebookApp]  or http://127.0.0.1:8889/?token=ead333178d7922419e7de2c698d79688c6202fe4ec4707fb
[I 09:47:54.948 NotebookApp] Use Control-C to stop this server and shut down all kernels (twice to skip confirmation).
[C 09:47:54.971 NotebookApp] 
    
    To access the notebook, open this file in a browser:
        file:///home/danil/.local/share/jupyter/runtime/nbserver-5072-open.html
    Or copy and paste one of these URLs:
        http://localhost:8889/?token=ead333178d7922419e7de2c698d79688c6202fe4ec4707fb
     or http://127.0.0.1:8889/?token=ead333178d7922419e7de2c698d79688c6202fe4ec4707fb
/usr/lib/python3.8/json/encoder.py:257: UserWarning: date_default is deprecated since jupyter_client 7.0.0. Use jupyter_client.jsonutil.json_default.
  return _iterencode(o, 0)
[W 09:48:10.017 NotebookApp] Notebook DataScience/EnsembleModels/EnsembleModels.ipynb is not trusted
ERROR:asyncio:Exception in callback <TaskWakeupMethWrapper object at 0x7f4025cd0a60>(<Future finis...464"\r\n\r\n'>)
handle: <Handle <TaskWakeupMethWrapper object at 0x7f4025cd0a60>(<Future finis...464"\r\n\r\n'>)>
Traceback (most recent call last):
  File "/usr/lib/python3.8/asyncio/events.py", line 81, in _run
    self._context.run(self._callback, *self._args)
RuntimeError: Cannot enter into task <Task pending name='Task-7' coro=<HTTP1ServerConnection._server_request_loop() running at /home/danil/.local/lib/python3.8/site-packages/tornado/http1connection.py:823> wait_for=<Future finished result=b'GET /api/co...e464"\r\n\r\n'> cb=[IOLoop.add_future.<locals>.<lambda>() at /home/danil/.local/lib/python3.8/site-packages/tornado/ioloop.py:688]> while another task <Task pending name='Task-2' coro=<KernelManager._async_start_kernel() running at /home/danil/.local/lib/python3.8/site-packages/jupyter_client/manager.py:336>> is being executed.
ERROR:asyncio:Exception in callback <TaskWakeupMethWrapper object at 0x7f40264f2670>(<Future finis...464"\r\n\r\n'>)
handle: <Handle <TaskWakeupMethWrapper object at 0x7f40264f2670>(<Future finis...464"\r\n\r\n'>)>
Traceback (most recent call last):
  File "/usr/lib/python3.8/asyncio/events.py", line 81, in _run
    self._context.run(self._callback, *self._args)
RuntimeError: Cannot enter into task <Task pending name='Task-5' coro=<HTTP1ServerConnection._server_request_loop() running at /home/danil/.local/lib/python3.8/site-packages/tornado/http1connection.py:823> wait_for=<Future finished result=b'GET /kernel...e464"\r\n\r\n'> cb=[IOLoop.add_future.<locals>.<lambda>() at /home/danil/.local/lib/python3.8/site-packages/tornado/ioloop.py:688]> while another task <Task pending name='Task-2' coro=<KernelManager._async_start_kernel() running at /home/danil/.local/lib/python3.8/site-packages/jupyter_client/manager.py:337>> is being executed.
[I 09:48:10.247 NotebookApp] Kernel started: f95b2809-d64d-4498-967b-e7361a7d94db, name: python3
[W 09:48:10.307 NotebookApp] 404 GET /nbextensions/widgets/notebook/js/extension.js?v=20221128094754 (127.0.0.1) 10.810000ms referer=http://localhost:8889/notebooks/DataScience/EnsembleModels/EnsembleModels.ipynb
[I 09:49:29.173 NotebookApp] Saving file at /DataScience/EnsembleModels/EnsembleModels.ipynb
[W 09:49:29.174 NotebookApp] Notebook DataScience/EnsembleModels/EnsembleModels.ipynb is not trusted
[I 09:50:10.247 NotebookApp] Saving file at /DataScience/EnsembleModels/EnsembleModels.ipynb
[W 09:50:10.248 NotebookApp] Notebook DataScience/EnsembleModels/EnsembleModels.ipynb is not trusted
[I 09:50:13.880 NotebookApp] Saving file at /DataScience/EnsembleModels/EnsembleModels.ipynb
[W 09:50:13.880 NotebookApp] Notebook DataScience/EnsembleModels/EnsembleModels.ipynb is not trusted
[I 09:52:10.276 NotebookApp] Saving file at /DataScience/EnsembleModels/EnsembleModels.ipynb
[W 09:52:10.276 NotebookApp] Notebook DataScience/EnsembleModels/EnsembleModels.ipynb is not trusted
[W 09:53:38.886 NotebookApp] Notebook DataScience/EnsembleModels/task-3.3.ipynb is not trusted
ERROR:asyncio:Exception in callback <TaskWakeupMethWrapper object at 0x7f4028141d30>(<Future finis...464"\r\n\r\n'>)
handle: <Handle <TaskWakeupMethWrapper object at 0x7f4028141d30>(<Future finis...464"\r\n\r\n'>)>
Traceback (most recent call last):
  File "/usr/lib/python3.8/asyncio/events.py", line 81, in _run
    self._context.run(self._callback, *self._args)
RuntimeError: Cannot enter into task <Task pending name='Task-1' coro=<HTTP1ServerConnection._server_request_loop() running at /home/danil/.local/lib/python3.8/site-packages/tornado/http1connection.py:823> wait_for=<Future finished result=b'GET /api/co...e464"\r\n\r\n'> cb=[IOLoop.add_future.<locals>.<lambda>() at /home/danil/.local/lib/python3.8/site-packages/tornado/ioloop.py:688]> while another task <Task pending name='Task-168' coro=<KernelManager._async_start_kernel() running at /home/danil/.local/lib/python3.8/site-packages/jupyter_client/manager.py:337>> is being executed.
[I 09:53:39.244 NotebookApp] Kernel started: 5ee742b6-3ea2-4766-9480-29b9f0eb613c, name: python3
[W 09:53:39.314 NotebookApp] 404 GET /nbextensions/widgets/notebook/js/extension.js?v=20221128094754 (127.0.0.1) 3.220000ms referer=http://localhost:8889/notebooks/DataScience/EnsembleModels/task-3.3.ipynb
[I 09:54:10.675 NotebookApp] Saving file at /DataScience/EnsembleModels/EnsembleModels.ipynb
[W 09:54:10.676 NotebookApp] Notebook DataScience/EnsembleModels/EnsembleModels.ipynb is not trusted
[W 09:55:08.422 NotebookApp] Notebook DataScience/MetricsOfModel/UsingOfMetrics.ipynb is not trusted
[I 09:55:08.824 NotebookApp] Kernel started: 78198fcd-0d15-4d4c-947e-f7e075d3d1c2, name: python3
[W 09:55:09.665 NotebookApp] 404 GET /nbextensions/widgets/notebook/js/extension.js?v=20221128094754 (127.0.0.1) 6.510000ms referer=http://localhost:8889/notebooks/DataScience/MetricsOfModel/UsingOfMetrics.ipynb
[I 09:55:39.705 NotebookApp] Saving file at /DataScience/EnsembleModels/task-3.3.ipynb
[I 09:55:59.509 NotebookApp] Kernel started: c62681f7-3575-4658-ba31-206333187194, name: python3
[W 09:55:59.591 NotebookApp] 404 GET /nbextensions/widgets/notebook/js/extension.js?v=20221128094754 (127.0.0.1) 5.020000ms referer=http://localhost:8889/notebooks/DataScience/MetricsOfModel/CourseraTask/regularization%20task.ipynb
[I 09:56:09.029 NotebookApp] Starting buffering for c62681f7-3575-4658-ba31-206333187194:20f45c2ce19047478c91e8596265311a
ERROR:asyncio:Exception in callback <TaskWakeupMethWrapper object at 0x7f4025070d30>(<Future finis...464"\r\n\r\n'>)
handle: <Handle <TaskWakeupMethWrapper object at 0x7f4025070d30>(<Future finis...464"\r\n\r\n'>)>
Traceback (most recent call last):
  File "/usr/lib/python3.8/asyncio/events.py", line 81, in _run
    self._context.run(self._callback, *self._args)
RuntimeError: Cannot enter into task <Task pending name='Task-8' coro=<HTTP1ServerConnection._server_request_loop() running at /home/danil/.local/lib/python3.8/site-packages/tornado/http1connection.py:823> wait_for=<Future finished result=b'GET /api/co...e464"\r\n\r\n'> cb=[IOLoop.add_future.<locals>.<lambda>() at /home/danil/.local/lib/python3.8/site-packages/tornado/ioloop.py:688]> while another task <Task pending name='Task-440' coro=<KernelManager._async_start_kernel() running at /home/danil/.local/lib/python3.8/site-packages/jupyter_client/manager.py:337>> is being executed.
[I 09:56:13.030 NotebookApp] Kernel started: c85e6e64-4cb6-4865-a339-9662ca903796, name: python3
[W 09:56:13.109 NotebookApp] 404 GET /nbextensions/widgets/notebook/js/extension.js?v=20221128094754 (127.0.0.1) 3.760000ms referer=http://localhost:8889/notebooks/DataScience/MetricsOfModel/CourseraTask/Metrics/task-3.2.2-solution.ipynb
[I 09:56:26.571 NotebookApp] Starting buffering for 78198fcd-0d15-4d4c-947e-f7e075d3d1c2:813c8c2ca1484d9d80488e730dd226a8
[I 09:57:39.269 NotebookApp] Saving file at /DataScience/EnsembleModels/task-3.3.ipynb
[I 09:59:39.261 NotebookApp] Saving file at /DataScience/EnsembleModels/task-3.3.ipynb
[I 10:01:39.261 NotebookApp] Saving file at /DataScience/EnsembleModels/task-3.3.ipynb
[I 10:03:39.262 NotebookApp] Saving file at /DataScience/EnsembleModels/task-3.3.ipynb
[I 10:09:39.259 NotebookApp] Saving file at /DataScience/EnsembleModels/task-3.3.ipynb
[I 10:11:39.263 NotebookApp] Saving file at /DataScience/EnsembleModels/task-3.3.ipynb
[I 10:13:39.681 NotebookApp] Saving file at /DataScience/EnsembleModels/task-3.3.ipynb
[W 10:13:47.923 NotebookApp] 404 GET /nbextensions/widgets/notebook/js/extension.js?v=20221128094754 (127.0.0.1) 3.030000ms referer=http://localhost:8889/notebooks/DataScience/MetricsOfModel/CourseraTask/Metrics/task-3.2.2-solution.ipynb
[W 10:14:08.272 NotebookApp] Notebook DataScience/EnsembleModels/task-3.3-solution.ipynb is not trusted
[I 10:14:08.629 NotebookApp] Kernel started: 5f953c23-37a3-4180-9fac-d99238311f94, name: python3
[W 10:14:08.687 NotebookApp] 404 GET /nbextensions/widgets/notebook/js/extension.js?v=20221128094754 (127.0.0.1) 2.920000ms referer=http://localhost:8889/notebooks/DataScience/EnsembleModels/task-3.3-solution.ipynb
[I 10:16:08.685 NotebookApp] Saving file at /DataScience/EnsembleModels/task-3.3-solution.ipynb
[I 10:17:39.258 NotebookApp] Saving file at /DataScience/EnsembleModels/task-3.3.ipynb
[I 10:19:39.684 NotebookApp] Saving file at /DataScience/EnsembleModels/task-3.3.ipynb
[I 10:20:08.659 NotebookApp] Saving file at /DataScience/EnsembleModels/task-3.3-solution.ipynb
[I 10:21:39.681 NotebookApp] Saving file at /DataScience/EnsembleModels/task-3.3.ipynb
[I 10:23:39.261 NotebookApp] Saving file at /DataScience/EnsembleModels/task-3.3.ipynb
[I 10:29:39.260 NotebookApp] Saving file at /DataScience/EnsembleModels/task-3.3.ipynb
[I 10:30:53.686 NotebookApp] Starting buffering for 5f953c23-37a3-4180-9fac-d99238311f94:add704672c0f4acaad99e8b8272b20ce
[I 10:30:54.124 NotebookApp] Kernel restarted: 5f953c23-37a3-4180-9fac-d99238311f94
[I 10:30:54.147 NotebookApp] Restoring connection for 5f953c23-37a3-4180-9fac-d99238311f94:add704672c0f4acaad99e8b8272b20ce
[I 10:30:54.692 NotebookApp] Replaying 3 buffered messages
[I 10:31:38.889 NotebookApp] Starting buffering for 5f953c23-37a3-4180-9fac-d99238311f94:add704672c0f4acaad99e8b8272b20ce
[I 10:31:39.213 NotebookApp] Kernel restarted: 5f953c23-37a3-4180-9fac-d99238311f94
[I 10:31:39.236 NotebookApp] Restoring connection for 5f953c23-37a3-4180-9fac-d99238311f94:add704672c0f4acaad99e8b8272b20ce
[I 10:31:39.663 NotebookApp] Saving file at /DataScience/EnsembleModels/task-3.3.ipynb
[I 10:31:39.837 NotebookApp] Replaying 3 buffered messages
[I 10:32:08.701 NotebookApp] Saving file at /DataScience/EnsembleModels/task-3.3-solution.ipynb
/usr/lib/python3.8/json/encoder.py:257: UserWarning: date_default is deprecated since jupyter_client 7.0.0. Use jupyter_client.jsonutil.json_default.
  return _iterencode(o, 0)
[C 11:30:13.572 NotebookApp] received signal 15, stopping
[I 11:30:13.572 NotebookApp] Shutting down 0 kernels
[I 11:30:13.574 NotebookApp] Shutting down 0 terminals
[I 11:30:13.682 NotebookApp] Starting buffering for 5ee742b6-3ea2-4766-9480-29b9f0eb613c:888459bb8eea4f87a18554dd6c253061
[I 11:30:13.684 NotebookApp] Starting buffering for f95b2809-d64d-4498-967b-e7361a7d94db:08a0811a04ea43fc9d7950dd297238db
[I 11:30:13.693 NotebookApp] Starting buffering for 5f953c23-37a3-4180-9fac-d99238311f94:add704672c0f4acaad99e8b8272b20ce
[I 11:30:13.700 NotebookApp] Starting buffering for c85e6e64-4cb6-4865-a339-9662ca903796:9175b765269243ceba66dab132cfcace
